Workbook

Sheet Trang bìa
B3: KHÁI TOÁN SƠ BỘ THỜI GIAN & CHI PHÍ
B5: Dự án Hệ sinh thái Mạng xã hội Taxi Web3 (SP1 Mạng xã hội Web3 · SP2 App linh kiện · SP3 AI Agent)
C8: Kính gửi | D8: Anh John Davis
C9: Người lập | D9: Lê Chí Tuyền – phân tích nghiệp vụ & điều phối dự án
C10: Ngày lập | D10: 30/10/2026
C11: Phạm vi | D11: 3 giai đoạn phần mềm, hạ tầng & dịch vụ bên thứ ba 12 tháng, chi phí một lần
C12: Mốc người dùng | D12: 3 tháng: 10.000 · 6 tháng: 100.000 · 12 tháng: 1.000.000
C13: Lưu ý | D13: Đây là khái toán sơ bộ để anh tham khảo, lập trên cơ sở trao đổi ngày 27/10/2026 và bộ mockup anh cung cấp. Báo giá chính thức sẽ gửi sau khi hai bên thống nhất phạm vi MVP, mô hình token và phương án hạ tầng.
B16: Phạm vi triển khai đề xuất chia thành 3 giai đoạn: - Giai đoạn 1 (tháng 0–3): MVP mạng xã hội Web3 – tài khoản, bảng tin, nhóm, sự kiện, ví VI, nhiệm vụ, Rewards Store, AI “Mai”, quản trị, app iOS/Android. - Giai đoạn 2 (tháng 3–6): đặt xe đa dịch vụ + app tài xế, SP2 app linh kiện, SP3 AI Agent mở rộng, khóa học, mentor. - Giai đoạn 3 (tháng 6–12): NFT, quản trị bằng token, marketplace, nền tảng đối tác, đa ngôn ngữ, đánh giá chuỗi riêng. - Hạ tầng: cloud, CDN, AI, SMS, bản đồ, blockchain tính theo mức sử dụng của từng mốc người dùng.

Sheet Tóm tắt
B2: TÓM TẮT KHÁI TOÁN DỰ ÁN TAXI SOCIAL WEB3
B4: Hệ sinh thái Mạng xã hội Taxi Web3 – Khái toán sơ bộ 3 giai đoạn
B6: Khối lượng phát triển (MD) | D6: Quản lý dự án, QA & bảo hành (MD) | F6: Tổng khối lượng (MD)
B7: ='Hạng mục công việc'!A4+'Hạng mục công việc'!B4+'Hạng mục công việc'!C4 -> 761 | D7: ='Hạng mục công việc'!D4+'Hạng mục công việc'!E4 -> 305.35 | F7: ='Hạng mục công việc'!F4 -> 1066.35
B9: Thời gian GĐ1 / GĐ2 / GĐ3 (tuần) | D9: Phần mềm sau VAT (VND) | F9: Tổng sau VAT gồm hạ tầng (VND)
B10: ='Lộ trình'!H4&" / "&'Lộ trình'!H5&" / "&'Lộ trình'!H6 -> 12 / 9 / 5 | D10: ='Tổng hợp chi phí'!D13 -> 3121123500 | F10: ='Tổng hợp chi phí'!D16 -> 5985523500
B13: Phạm vi triển khai
B14: Giai đoạn 1 | C14: 0–3 tháng · 10.000 người dùng: MVP mạng xã hội Web3 – tài khoản, bảng tin, nhóm, sự kiện, ví VI, nhiệm vụ, Rewards Store, AI “Mai”, quản trị, app iOS/Android.
B15: Giai đoạn 2 | C15: 3–6 tháng · 100.000 người dùng: đặt xe đa dịch vụ + app tài xế, SP2 app linh kiện, SP3 AI Agent mở rộng, khóa học, mentor.
B16: Giai đoạn 3 | C16: 6–12 tháng · 1.000.000 người dùng: NFT, quản trị bằng token, marketplace, nền tảng đối tác, đa ngôn ngữ, đánh giá chuỗi riêng.
B17: Hạ tầng | C17: Cloud, CDN, AI, SMS, bản đồ, blockchain Layer 2 theo mức sử dụng 12 tháng; kiểm toán smart contract là chi phí một lần.
B19: Cơ cấu chi phí
B20: Hạng mục | C20: Khối lượng (MD) | D20: Đơn giá | E20: Thành tiền | F20: Ghi chú
B21: ='Tổng hợp chi phí'!A4 -> Phát triển phần mềm Giai đoạn 1 | C21: ='Tổng hợp chi phí'!B4 -> 384 | D21: ='Tổng hợp chi phí'!C4 -> 2500000 | E21: ='Tổng hợp chi phí'!D4 -> 960000000 | F21: ='Tổng hợp chi phí'!E4 -> MVP mạng xã hội Web3
B22: ='Tổng hợp chi phí'!A5 -> Phát triển phần mềm Giai đoạn 2 | C22: ='Tổng hợp chi phí'!B5 -> 270.5 | D22: ='Tổng hợp chi phí'!C5 -> 2500000 | E22: ='Tổng hợp chi phí'!D5 -> 676250000 | F22: ='Tổng hợp chi phí'!E5 -> Đặt xe, SP2, SP3
B23: ='Tổng hợp chi phí'!A6 -> Phát triển phần mềm Giai đoạn 3 | C23: ='Tổng hợp chi phí'!B6 -> 106.5 | D23: ='Tổng hợp chi phí'!C6 -> 2500000 | E23: ='Tổng hợp chi phí'!D6 -> 266250000 | F23: ='Tổng hợp chi phí'!E6 -> Hệ sinh thái Web3
B24: ='Tổng hợp chi phí'!A7 -> Bảo hành, hỗ trợ 12 tháng | C24: ='Tổng hợp chi phí'!B7 -> 39 | D24: ='Tổng hợp chi phí'!C7 -> 2800000 | E24: ='Tổng hợp chi phí'!D7 -> 109200000 | F24: ='Tổng hợp chi phí'!E7 -> Từ khi go-live giai đoạn 1
B25: ='Tổng hợp chi phí'!A8 -> Quản lý dự án, kiểm soát chất lượng & rủi ro | C25: ='Tổng hợp chi phí'!B8 -> 266.35 | D25: ='Tổng hợp chi phí'!C8 -> 3100000 | E25: ='Tổng hợp chi phí'!D8 -> 825685000 | F25: ='Tổng hợp chi phí'!E8 -> Theo tỷ lệ trên khối lượng phát triển
B26: ='Tổng hợp chi phí'!A9 -> Hạ tầng & dịch vụ bên thứ ba (12 tháng) | C26: ='Tổng hợp chi phí'!B9 -> - | D26: ='Tổng hợp chi phí'!C9 -> - | E26: ='Tổng hợp chi phí'!D9 -> 2349000000 | F26: ='Tổng hợp chi phí'!E9 -> Theo mức sử dụng thực tế
B27: ='Tổng hợp chi phí'!A10 -> Chi phí một lần (kiểm toán smart contract…) | C27: ='Tổng hợp chi phí'!B10 -> - | D27: ='Tổng hợp chi phí'!C10 -> - | E27: ='Tổng hợp chi phí'!D10 -> 255000000 | F27: ='Tổng hợp chi phí'!E10 -> Tính vào giai đoạn 1
B28: Tổng phần mềm sau VAT | E28: ='Tổng hợp chi phí'!D13 -> 3121123500
B29: Tổng trước VAT gồm hạ tầng | E29: ='Tổng hợp chi phí'!D14 -> 5441385000
B30: Tổng sau VAT gồm hạ tầng | E30: ='Tổng hợp chi phí'!D16 -> 5985523500
B32: Phân bổ chi phí theo giai đoạn
B33: Giai đoạn | C33: Phát triển | D33: Quản lý dự án | E33: Hạ tầng | F33: Một lần | G33: Trước VAT | H33: Sau VAT
B34: ='Tổng hợp chi phí'!A20 -> Giai đoạn 1 | C34: ='Tổng hợp chi phí'!B20 -> 960000000 | D34: ='Tổng hợp chi phí'!C20 -> 416640000 | E34: ='Tổng hợp chi phí'!D20 -> 90000000 | F34: ='Tổng hợp chi phí'!E20 -> 255000000 | G34: ='Tổng hợp chi phí'!G20 -> 1721640000 | H34: ='Tổng hợp chi phí'!I20 -> 1893804000
B35: ='Tổng hợp chi phí'!A21 -> Giai đoạn 2 | C35: ='Tổng hợp chi phí'!B21 -> 676250000 | D35: ='Tổng hợp chi phí'!C21 -> 293492500 | E35: ='Tổng hợp chi phí'!D21 -> 309000000 | F35: ='Tổng hợp chi phí'!E21 -> 0 | G35: ='Tổng hợp chi phí'!G21 -> 1278742500 | H35: ='Tổng hợp chi phí'!I21 -> 1406616750
B36: ='Tổng hợp chi phí'!A22 -> Giai đoạn 3 | C36: ='Tổng hợp chi phí'!B22 -> 266250000 | D36: ='Tổng hợp chi phí'!C22 -> 115552500 | E36: ='Tổng hợp chi phí'!D22 -> 1950000000 | F36: ='Tổng hợp chi phí'!E22 -> 0 | G36: ='Tổng hợp chi phí'!G22 -> 2331802500 | H36: ='Tổng hợp chi phí'!I22 -> 2564982750
B37: ='Tổng hợp chi phí'!A23 -> Bảo hành, hỗ trợ 12 tháng | C37: ='Tổng hợp chi phí'!B23 -> 0 | D37: ='Tổng hợp chi phí'!C23 -> 0 | E37: ='Tổng hợp chi phí'!D23 -> 0 | F37: ='Tổng hợp chi phí'!E23 -> 0 | G37: ='Tổng hợp chi phí'!G23 -> 109200000 | H37: ='Tổng hợp chi phí'!I23 -> 120120000
B38: ='Tổng hợp chi phí'!A24 -> TỔNG CỘNG | C38: ='Tổng hợp chi phí'!B24 -> 1902500000 | D38: ='Tổng hợp chi phí'!C24 -> 825685000 | E38: ='Tổng hợp chi phí'!D24 -> 2349000000 | F38: ='Tổng hợp chi phí'!E24 -> 255000000 | G38: ='Tổng hợp chi phí'!G24 -> 5441385000 | H38: ='Tổng hợp chi phí'!I24 -> 5985523500
B40: Khái toán sơ bộ để anh tham khảo. Báo giá chính thức sẽ gửi sau khi hai bên thống nhất phạm vi MVP, mô hình token và phương án hạ tầng.

Sheet Đơn giá & giả định
A1: ĐƠN GIÁ & GIẢ ĐỊNH
A3: Thông số | B3: Giá trị | C3: Đơn vị | D3: Ghi chú
A4: Đơn giá phát triển | B4: 2500000 | C4: VND/MD | D4: Bình quân phân tích, thiết kế, lập trình, kiểm thử
A5: Đơn giá bảo hành / hỗ trợ | B5: 2800000 | C5: VND/MD | D5: Bảo hành, hỗ trợ, bảo trì sau go-live
A6: Đơn giá quản lý dự án | B6: 3100000 | C6: VND/MD | D6: Quản lý dự án, kiểm soát chất lượng & rủi ro
A7: Tỷ lệ quản lý dự án, QA & rủi ro | B7: 0.35 | C7: % | D7: Tính trên khối lượng phát triển 3 giai đoạn
A8: Năng lực đội dự án | B8: 40 | C8: MD/tuần | D8: Khoảng 8–9 người để kịp mốc 3 tháng
A9: VAT | B9: 0.1 | C9: %
A10: Số tháng mốc 1 (10.000 người dùng) | B10: 3 | C10: tháng | D10: Hạ tầng tháng 1–3
A11: Số tháng mốc 2 (100.000 người dùng) | B11: 3 | C11: tháng | D11: Hạ tầng tháng 4–6
A12: Số tháng mốc 3 (1.000.000 người dùng) | B12: 6 | C12: tháng | D12: Hạ tầng tháng 7–12

Sheet Hạng mục công việc
A1: DANH SÁCH HẠNG MỤC & KHỐI LƯỢNG CÔNG VIỆC
A3: GĐ1 (MD) | B3: GĐ2 (MD) | C3: GĐ3 (MD) | D3: Bảo hành (MD) | E3: QLDA, QA & rủi ro (MD) | F3: Tổng (MD)
A4: =SUMIF($E$8:$E$78,"GĐ1",$D$8:$D$78) -> 384 | B4: =SUMIF($E$8:$E$78,"GĐ2",$D$8:$D$78) -> 270.5 | C4: =SUMIF($E$8:$E$78,"GĐ3",$D$8:$D$78) -> 106.5 | D4: =SUMIF($E$8:$E$78,"Bảo hành",$D$8:$D$78) -> 39 | E4: =(A4+B4+C4)*'Đơn giá & giả định'!B7 -> 266.35 | F4: =SUM(A4:E4) -> 1066.35
A5: MD (man-day) = 1 người làm việc 1 ngày. Khối lượng mỗi hạng mục đã gồm phân tích, thiết kế, lập trình và kiểm thử.
A7: STT | B7: Nhóm chức năng | C7: Hạng mục | D7: Khối lượng (MD) | E7: Giai đoạn | F7: Ghi chú
A8: I. Công việc chung
A9: 1 | B9: Khảo sát, phân tích nghiệp vụ 3 sản phẩm, lập URD/SRS | C9: - | D9: 16 | E9: GĐ1 | F9: Gồm workshop chốt MVP và mô hình token
A10: 2 | B10: Thiết kế UI/UX: web, app hành khách, app tài xế, admin (dựa trên mockup KH) | C10: - | D10: 32.5 | E10: GĐ1 | F10: Design system, prototype
A11: 3 | B11: Thiết kế kiến trúc mở rộng tới 1 triệu người dùng, mô hình dữ liệu | C11: - | D11: 10.5 | E11: GĐ1
A12: 4 | B12: Thiết kế mô hình token, smart contract, phương án ví (phối hợp pháp lý) | C12: - | D12: 8 | E12: GĐ1 | F12: Tư vấn pháp lý do anh chủ động
A13: 5 | B13: Cấu hình môi trường, CI/CD, Docker/Kubernetes, giám sát, backup | C13: - | D13: 13 | E13: GĐ1
A14: 6 | B14: Kiểm thử tải mốc 10.000 người dùng | C14: - | D14: 5.5 | E14: GĐ1
A15: 7 | B15: UAT, phát hành App Store/Google Play, go-live GĐ1 | C15: - | D15: 13 | E15: GĐ1
A16: 8 | B16: Tài liệu dự án, hướng dẫn sử dụng, vận hành | C16: - | D16: 8 | E16: GĐ1
A17: 9 | B17: Kiểm thử tải mốc 100.000 người dùng, UAT & go-live GĐ2 | C17: - | D17: 13 | E17: GĐ2
A18: 10 | B18: Kiểm thử tải mốc 1.000.000 người dùng, UAT & go-live GĐ3 | C18: - | D18: 16 | E18: GĐ3
A19: 11 | B19: Bảo hành, hỗ trợ, bảo trì 12 tháng | C19: - | D19: 39 | E19: Bảo hành | F19: Không tính vào tiến độ go-live
A20: II. Chức năng nghiệp vụ
A21: 1 | B21: I. Tài khoản & hồ sơ người dùng | C21: Đăng ký/đăng nhập SĐT (OTP), Facebook, Google | D21: 6.5 | E21: GĐ1
C22: Vai trò Tài xế/Hành khách/Đối tác, xác minh tài khoản (tick xanh) | D22: 5.5 | E22: GĐ1
C23: Hồ sơ: followers, điểm, huy hiệu, bài viết, thành tích; Ride Passport cơ bản | D23: 8 | E23: GĐ1
C24: Mời bạn (referral), link mời từ nhóm Facebook | D24: 4 | E24: GĐ1
A25: 2 | B25: II. Mạng xã hội (SP1) | C25: Bảng tin For you / Following / Nearby / Discover, xếp hạng cơ bản | D25: 16 | E25: GĐ1
C26: Đăng bài ảnh/video, nén & xử lý media, phân phối qua CDN | D26: 13 | E26: GĐ1
C27: Thích, bình luận, chia sẻ, theo dõi | D27: 8 | E27: GĐ1
C28: Nhóm cộng đồng: tạo, tham gia, gợi ý, gần tôi, thịnh hành | D28: 10.5 | E28: GĐ1
C29: Chủ đề thịnh hành, tìm kiếm bài viết/người dùng/nhóm/địa điểm | D29: 8 | E29: GĐ1
C30: Thông báo push & trong ứng dụng | D30: 6.5 | E30: GĐ1
C31: Nhắn tin 1-1 realtime | D31: 13 | E31: GĐ1
C32: Báo cáo vi phạm, kiểm duyệt nội dung (AI lọc tự động + duyệt tay) | D32: 10.5 | E32: GĐ1
C33: Sự kiện: sắp diễn ra, online, gần tôi, đăng ký tham gia | D33: 8 | E33: GĐ1
A34: 3 | B34: III. Ví VI & phần thưởng (Web3) | C34: Smart contract token ERC-20 trên Ethereum Layer 2, kiểm thử | D34: 10.5 | E34: GĐ1
C35: Ví tạo tự động, quản lý khóa an toàn (KMS) | D35: 13 | E35: GĐ1
C36: Liên kết ví ngoài (MetaMask, WalletConnect) | D36: 5.5 | E36: GĐ1
C37: Sổ điểm off-chain, quyết toán định kỳ lên chuỗi | D37: 13 | E37: GĐ1
C38: Nạp, gửi, nhận, lịch sử giao dịch | D38: 8 | E38: GĐ1
C39: Engine nhiệm vụ & quy tắc kiếm điểm, chống gian lận săn thưởng | D39: 13 | E39: GĐ1
C40: Rewards Store: đổi ưu đãi nhiên liệu, mua sắm, du lịch | D40: 10.5 | E40: GĐ1
C41: Bảng xếp hạng, huy hiệu, thử thách theo mùa | D41: 5.5 | E41: GĐ1
A42: 4 | B42: IV. AI trợ lý “Mai” – bản đầu (SP3) | C42: Chatbot hỏi đáp 24/7 (LLM + tri thức nền tảng) | D42: 13 | E42: GĐ1
...

Sheet Hạ tầng 12 tháng
A1: KHÁI TOÁN HẠ TẦNG & DỊCH VỤ BÊN THỨ BA (12 THÁNG)
A3: STT | B3: Hạng mục | C3: Mốc 1 · 10.000 người dùng (VND/tháng) | D3: Mốc 2 · 100.000 người dùng (VND/tháng) | E3: Mốc 3 · 1 triệu người dùng (VND/tháng) | F3: Thành tiền 12 tháng | G3: Ghi chú
A4: 1 | B4: Máy chủ ứng dụng (Kubernetes, tự mở rộng) | C4: 8000000 | D4: 20000000 | E4: 60000000 | F4: =C4*'Đơn giá & giả định'!$B$10+D4*'Đơn giá & giả định'!$B$11+E4*'Đơn giá & giả định'!$B$12 -> 444000000 | G4: Theo số người dùng hoạt động
A5: 2 | B5: CSDL PostgreSQL + Redis (managed) | C5: 6000000 | D5: 15000000 | E5: 40000000 | F5: =C5*'Đơn giá & giả định'!$B$10+D5*'Đơn giá & giả định'!$B$11+E5*'Đơn giá & giả định'!$B$12 -> 303000000 | G5: Có bản sao dự phòng
A6: 3 | B6: Lưu trữ ảnh/video + CDN | C6: 3000000 | D6: 15000000 | E6: 60000000 | F6: =C6*'Đơn giá & giả định'!$B$10+D6*'Đơn giá & giả định'!$B$11+E6*'Đơn giá & giả định'!$B$12 -> 414000000 | G6: Phụ thuộc lượng video
A7: 4 | B7: Tìm kiếm, hàng đợi sự kiện, log & giám sát | C7: 3000000 | D7: 8000000 | E7: 20000000 | F7: =C7*'Đơn giá & giả định'!$B$10+D7*'Đơn giá & giả định'!$B$11+E7*'Đơn giá & giả định'!$B$12 -> 153000000
A8: 5 | B8: Blockchain: RPC node + phí gas Layer 2 | C8: 2000000 | D8: 5000000 | E8: 15000000 | F8: =C8*'Đơn giá & giả định'!$B$10+D8*'Đơn giá & giả định'!$B$11+E8*'Đơn giá & giả định'!$B$12 -> 111000000 | G8: Quyết toán theo lô giúp giảm phí
A9: 6 | B9: AI/LLM API (chatbot, dịch, kiểm duyệt) | C9: 5000000 | D9: 25000000 | E9: 80000000 | F9: =C9*'Đơn giá & giả định'!$B$10+D9*'Đơn giá & giả định'!$B$11+E9*'Đơn giá & giả định'!$B$12 -> 570000000 | G9: Phụ thuộc số lượt hỏi
A10: 7 | B10: SMS OTP, bản đồ, push notification | C10: 3000000 | D10: 15000000 | E10: 50000000 | F10: =C10*'Đơn giá & giả định'!$B$10+D10*'Đơn giá & giả định'!$B$11+E10*'Đơn giá & giả định'!$B$12 -> 354000000 | G10: Bản đồ tăng mạnh khi có đặt xe
B11: TỔNG / THÁNG & 12 THÁNG | C11: =SUM(C4:C10) -> 30000000 | D11: =SUM(D4:D10) -> 103000000 | E11: =SUM(E4:E10) -> 325000000 | F11: =SUM(F4:F10) -> 2349000000 | G11: Thanh toán theo mức sử dụng thực tế
B13: Phân bổ theo giai đoạn | C13: =C11*'Đơn giá & giả định'!B10 -> 90000000 | D13: =D11*'Đơn giá & giả định'!B11 -> 309000000 | E13: =E11*'Đơn giá & giả định'!B12 -> 1950000000
C14: GĐ1 | D14: GĐ2 | E14: GĐ3
A16: Chi phí hạ tầng trả trực tiếp cho nhà cung cấp cloud/dịch vụ, phụ thuộc số người dùng hoạt động và lượng ảnh/video, lượt dùng AI, bản đồ thực tế. Bên tư vấn sẽ tối ưu cấu hình trong quá trình vận hành.

Sheet Chi phí một lần
A1: CHI PHÍ MỘT LẦN (TÍNH VÀO GIAI ĐOẠN 1)
A3: STT | B3: Hạng mục | C3: SL | D3: Đơn giá | E3: Thành tiền | F3: Ghi chú
A4: 1 | B4: Kiểm toán bảo mật smart contract (đơn vị độc lập) | C4: 1 | D4: 250000000 | E4: =C4*D4 -> 250000000 | F4: Bắt buộc trước khi phát hành token; tùy chọn nhà cung cấp
A5: 2 | B5: Tài khoản nhà phát triển Apple/Google, chứng thư SSL | C5: 1 | D5: 5000000 | E5: =C5*D5 -> 5000000 | F5: Theo năm
B6: TỔNG CHI PHÍ MỘT LẦN | E6: =SUM(E4:E5) -> 255000000
A8: Chưa gồm: tư vấn pháp lý về token, chi phí niêm yết token (nếu có), marketing thu hút người dùng, nhân sự kiểm duyệt nội dung.

Sheet Lộ trình
A1: LỘ TRÌNH TRIỂN KHAI DỰ KIẾN
A3: STT | B3: Giai đoạn | C3: Mục tiêu | D3: Khối lượng (MD) | E3: Năng lực đội (MD/tuần) | F3: Tuần làm việc | G3: Dự phòng (tuần) | H3: Kế hoạch (tuần)
A4: 1 | B4: Giai đoạn 1 - MVP mạng xã hội Web3 | C4: Tài khoản, bảng tin, nhóm, sự kiện, ví VI, nhiệm vụ, Rewards Store, AI “Mai”, quản trị, app di động | D4: =SUMIF('Hạng mục công việc'!$E$8:$E$78,"GĐ1",'Hạng mục công việc'!$D$8:$D$78) -> 384 | E4: ='Đơn giá & giả định'!$B$8 -> 40 | F4: =ROUNDUP(D4/E4,0) -> 10 | G4: 2 | H4: =F4+G4 -> 12
A5: 2 | B5: Giai đoạn 2 - Dịch vụ, SP2, SP3 | C5: Đặt xe + app tài xế, app linh kiện, AI Agent mở rộng, khóa học, mentor | D5: =SUMIF('Hạng mục công việc'!$E$8:$E$78,"GĐ2",'Hạng mục công việc'!$D$8:$D$78) -> 270.5 | E5: ='Đơn giá & giả định'!$B$8 -> 40 | F5: =ROUNDUP(D5/E5,0) -> 7 | G5: 2 | H5: =F5+G5 -> 9
A6: 3 | B6: Giai đoạn 3 - Hệ sinh thái Web3 | C6: NFT, quản trị bằng token, marketplace, nền tảng đối tác, đa ngôn ngữ | D6: =SUMIF('Hạng mục công việc'!$E$8:$E$78,"GĐ3",'Hạng mục công việc'!$D$8:$D$78) -> 106.5 | E6: ='Đơn giá & giả định'!$B$8 -> 40 | F6: =ROUNDUP(D6/E6,0) -> 3 | G6: 2 | H6: =F6+G6 -> 5
A7: TỔNG THỜI GIAN TRIỂN KHAI (tuần) | H7: =SUM(H4:H6) -> 26
A9: - Giai đoạn 1 hoàn thành trong khoảng 3 tháng, kịp mốc 10.000 người dùng. - Giai đoạn 2 hoàn thành trước mốc 6 tháng (100.000 người dùng). - Giai đoạn 3 hoàn thành sớm; thời gian còn lại đến tháng 12 dành cho vận hành, tối ưu và tăng trưởng lên 1 triệu người dùng. - Bảo hành, hỗ trợ 12 tháng tính từ khi go-live giai đoạn 1.

Sheet Tổng hợp chi phí
A1: TỔNG HỢP KHÁI TOÁN CHI PHÍ
A3: Hạng mục | B3: Khối lượng (MD) | C3: Đơn giá (VND/MD) | D3: Thành tiền (VND) | E3: Ghi chú
A4: Phát triển phần mềm Giai đoạn 1 | B4: =SUMIF('Hạng mục công việc'!$E$8:$E$78,"GĐ1",'Hạng mục công việc'!$D$8:$D$78) -> 384 | C4: ='Đơn giá & giả định'!B4 -> 2500000 | D4: =B4*C4 -> 960000000 | E4: MVP mạng xã hội Web3
A5: Phát triển phần mềm Giai đoạn 2 | B5: =SUMIF('Hạng mục công việc'!$E$8:$E$78,"GĐ2",'Hạng mục công việc'!$D$8:$D$78) -> 270.5 | C5: ='Đơn giá & giả định'!B4 -> 2500000 | D5: =B5*C5 -> 676250000 | E5: Đặt xe, SP2, SP3
A6: Phát triển phần mềm Giai đoạn 3 | B6: =SUMIF('Hạng mục công việc'!$E$8:$E$78,"GĐ3",'Hạng mục công việc'!$D$8:$D$78) -> 106.5 | C6: ='Đơn giá & giả định'!B4 -> 2500000 | D6: =B6*C6 -> 266250000 | E6: Hệ sinh thái Web3
A7: Bảo hành, hỗ trợ 12 tháng | B7: =SUMIF('Hạng mục công việc'!$E$8:$E$78,"Bảo hành",'Hạng mục công việc'!$D$8:$D$78) -> 39 | C7: ='Đơn giá & giả định'!B5 -> 2800000 | D7: =B7*C7 -> 109200000 | E7: Từ khi go-live giai đoạn 1
A8: Quản lý dự án, kiểm soát chất lượng & rủi ro | B8: =(SUMIF('Hạng mục công việc'!$E$8:$E$78,"GĐ1",'Hạng mục công việc'!$D$8:$D$78)+SUMIF('Hạng mục công việc'!$E$8:$E$78,"GĐ2",'Hạng mục công việc'!$D$8:$D$78)+SUMIF('Hạng mục công việc'!$E$8:$E$78,"GĐ3",'Hạng mục công việc'!$D$8:$D$78))*'Đơn giá & giả định'!B7 -> 266.35 | C8: ='Đơn giá & giả định'!B6 -> 3100000 | D8: =B8*C8 -> 825685000 | E8: Theo tỷ lệ trên khối lượng phát triển
A9: Hạ tầng & dịch vụ bên thứ ba (12 tháng) | B9: - | C9: - | D9: ='Hạ tầng 12 tháng'!$F$11 -> 2349000000 | E9: Theo mức sử dụng thực tế
A10: Chi phí một lần (kiểm toán smart contract…) | B10: - | C10: - | D10: ='Chi phí một lần'!$E$6 -> 255000000 | E10: Tính vào giai đoạn 1
A11: TỔNG PHẦN MỀM TRƯỚC VAT | D11: =SUM(D4:D8) -> 2837385000
A12: VAT | D12: =D11*'Đơn giá & giả định'!B9 -> 283738500
A13: TỔNG PHẦN MỀM SAU VAT | D13: =D11+D12 -> 3121123500
A14: TỔNG TRƯỚC VAT (gồm hạ tầng & chi phí một lần) | D14: =D11+D9+D10 -> 5441385000
A15: VAT | D15: =D14*'Đơn giá & giả định'!B9 -> 544138500
A16: TỔNG SAU VAT (gồm hạ tầng & chi phí một lần) | D16: =D14+D15 -> 5985523500 | E16: Khái toán sơ bộ
A18: PHÂN BỔ CHI PHÍ THEO GIAI ĐOẠN
A19: Giai đoạn | B19: Phát triển | C19: Quản lý dự án | D19: Hạ tầng | E19: Chi phí một lần | F19: Bảo hành | G19: Tổng trước VAT | H19: VAT | I19: Tổng sau VAT
A20: Giai đoạn 1 | B20: =SUMIF('Hạng mục công việc'!$E$8:$E$78,"GĐ1",'Hạng mục công việc'!$D$8:$D$78)*'Đơn giá & giả định'!$B$4 -> 960000000 | C20: =$D$8*SUMIF('Hạng mục công việc'!$E$8:$E$78,"GĐ1",'Hạng mục công việc'!$D$8:$D$78)/(SUMIF('Hạng mục công việc'!$E$8:$E$78,"GĐ1",'Hạng mục công việc'!$D$8:$D$78)+SUMIF('Hạng mục công việc'!$E$8:$E$78,"GĐ2",'Hạng mục công việc'!$D$8:$D$78)+SUMIF('Hạng mục công việc'!$E$8:$E$78,"GĐ3",'Hạng mục công việc'!$D$8:$D$78)) -> 416640000 | D20: ='Hạ tầng 12 tháng'!$C$13 -> 90000000 | E20: ='Chi phí một lần'!$E$6 -> 255000000 | F20: 0 | G20: =SUM(B20:F20) -> 1721640000 | H20: =G20*'Đơn giá & giả định'!$B$9 -> 172164000 | I20: =G20+H20 -> 1893804000
A21: Giai đoạn 2 | B21: =SUMIF('Hạng mục công việc'!$E$8:$E$78,"GĐ2",'Hạng mục công việc'!$D$8:$D$78)*'Đơn giá & giả định'!$B$4 -> 676250000 | C21: =$D$8*SUMIF('Hạng mục công việc'!$E$8:$E$78,"GĐ2",'Hạng mục công việc'!$D$8:$D$78)/(SUMIF('Hạng mục công việc'!$E$8:$E$78,"GĐ1",'Hạng mục công việc'!$D$8:$D$78)+SUMIF('Hạng mục công việc'!$E$8:$E$78,"GĐ2",'Hạng mục công việc'!$D$8:$D$78)+SUMIF('Hạng mục công việc'!$E$8:$E$78,"GĐ3",'Hạng mục công việc'!$D$8:$D$78)) -> 293492500 | D21: ='Hạ tầng 12 tháng'!$D$13 -> 309000000 | E21: 0 | F21: 0 | G21: =SUM(B21:F21) -> 1278742500 | H21: =G21*'Đơn giá & giả định'!$B$9 -> 127874250 | I21: =G21+H21 -> 1406616750
A22: Giai đoạn 3 | B22: =SUMIF('Hạng mục công việc'!$E$8:$E$78,"GĐ3",'Hạng mục công việc'!$D$8:$D$78)*'Đơn giá & giả định'!$B$4 -> 266250000 | C22: =$D$8*SUMIF('Hạng mục công việc'!$E$8:$E$78,"GĐ3",'Hạng mục công việc'!$D$8:$D$78)/(SUMIF('Hạng mục công việc'!$E$8:$E$78,"GĐ1",'Hạng mục công việc'!$D$8:$D$78)+SUMIF('Hạng mục công việc'!$E$8:$E$78,"GĐ2",'Hạng mục công việc'!$D$8:$D$78)+SUMIF('Hạng mục công việc'!$E$8:$E$78,"GĐ3",'Hạng mục công việc'!$D$8:$D$78)) -> 115552500 | D22: ='Hạ tầng 12 tháng'!$E$13 -> 1950000000 | E22: 0 | F22: 0 | G22: =SUM(B22:F22) -> 2331802500 | H22: =G22*'Đơn giá & giả định'!$B$9 -> 233180250 | I22: =G22+H22 -> 2564982750
A23: Bảo hành, hỗ trợ 12 tháng | B23: 0 | C23: 0 | D23: 0 | E23: 0 | F23: =$D$7 -> 109200000 | G23: =SUM(B23:F23) -> 109200000 | H23: =G23*'Đơn giá & giả định'!$B$9 -> 10920000 | I23: =G23+H23 -> 120120000
A24: TỔNG CỘNG | B24: =SUM(B20:B23) -> 1902500000 | C24: =SUM(C20:C23) -> 825685000 | D24: =SUM(D20:D23) -> 2349000000 | E24: =SUM(E20:E23) -> 255000000 | F24: =SUM(F20:F23) -> 109200000 | G24: =SUM(G20:G23) -> 5441385000 | H24: =SUM(H20:H23) -> 544138500 | I24: =SUM(I20:I23) -> 5985523500
A26: Ghi chú: - Chi phí quản lý dự án phân bổ theo tỷ trọng khối lượng phát triển của từng giai đoạn. - Hạ tầng phân bổ theo số tháng của từng mốc người dùng (GĐ1: tháng 1–3, GĐ2: tháng 4–6, GĐ3: tháng 7–12). - Chi phí một lần (kiểm toán smart contract, tài khoản nhà phát triển) tính vào giai đoạn 1. - Chưa gồm tư vấn pháp lý về token, marketing, nhân sự kiểm duyệt nội dung.
